Workbook
Name Slicer_Age_Group_Class: #N/A
Name Slicer_Date_Year: #N/A
Name Slicer_MD_Short: #N/A
Name Slicer_Risk_Tier: #N/A
Name Slicer_Short_Month: #N/A

Sheet Pivots
A3: Total Appointment | E3: Total Revenue | I3: Total Operational Cost | M3: Total Overtime Hours
A4: 2505 | E4: 22826272 | I4: 15473835 | M4: 21025.4
G5: [$$-en-US][>=1000000]#,##0.00,,"M";[>=1000#,##0.0,"K";#,##0
A8: Department | B8: Total Appointment | E8: Months | F8: Total Revenue | I8: Department | J8: Total Revenue | M8: Age Group | N8: Total Appointment
A9: Cardio | B9: 342 | E9: Jan | F9: 1749341.3 | I9: Cardiology | J9: 3245463.5 | M9: Adult | N9: 1287
A10: ICU | B10: 341 | E10: Feb | F10: 1846072.3 | I10: Emergency Room | J10: 2190568.7 | M10: Geriatric | N10: 900
A11: Neuro | B11: 330 | E11: Mar | F11: 1996281.7 | I11: General Medicine | J11: 1009094.8 | M11: Pediatric | N11: 318
A12: ER | B12: 319 | E12: Apr | F12: 2008475.3 | I12: Intensive Care Unit | J12: 5587597.8
A13: PD | B13: 301 | E13: May | F13: 2188857.8 | I13: Neurology | J13: 3006250.4
A14: Surgery | B14: 298 | E14: Jun | F14: 2162640.2 | I14: Orthopedics | J14: 2201025.7
A15: GM | B15: 293 | E15: Jul | F15: 2007985.2 | I15: Pediatrics | J15: 522488.67
A16: Ortho | B16: 281 | E16: Aug | F16: 1235909 | I16: Surgery | J16: 5063782.7
E17: Sep | F17: 1749732 | M17: Clinical Status | N17: Total Appointment
A18: Month | B18: Count of Patient_ID | E18: Oct | F18: 2014370.2 | M18: Discharged | N18: 0.54730539
A19: Jan | B19: 209 | E19: Nov | F19: 1817058.9 | M19: In-Patient Care | N19: 0.28303393
A20: Feb | B20: 214 | E20: Dec | F20: 2049548.4 | I20: Row Labels | J20: Sum of Staff_Overtime_Hrs | M20: Readmitted | N20: 0.16966068
A21: Mar | B21: 219 | I21: 2023 | J21: 2296
A22: Apr | B22: 226 | I22: 2024 | J22: 7181
A23: May | B23: 236 | I23: 2025 | J23: 7418 | L23: Year | M23: Operational Cost | N23: Revenue
A24: Jun | B24: 233 | I24: 2026 | J24: 4130.4 | L24: 2026 | M24: 3052325.9 | N24: 4516068.9
A25: Jul | B25: 210 | I25: Grand Total | J25: 21025.4 | L25: 2025 | M25: 5541248.5 | N25: 8177217.5
A26: Aug | B26: 135 | L26: 2024 | M26: 5167705.1 | N26: 7606763.7
A27: Sep | B27: 187 | L27: 2023 | M27: 1712555.4 | N27: 2526222.3
A28: Oct | B28: 209 | L28: Grand Total | M28: 15473835 | N28: 22826272
A29: Nov | B29: 198
A30: Dec | B30: 229
A31: Grand Total | B31: 2505

Sheet KPI
B10: 1) Total Appointment | C10: =GETPIVOTDATA("Patient_ID",Pivots!$A$3) -> 2505
B11: 2) Total Revenue | C11: =GETPIVOTDATA("Patient_Bill",Pivots!$E$3) -> 22826272
B12: 3) Total Operational Cost | C12: =GETPIVOTDATA("Operational_Cost",Pivots!$I$3) -> 15473835
B13: 4) Total Profit | C13: =C11-C12 -> 7352437.5
B14: 5) Total Staff Overtime | C14: =GETPIVOTDATA("Staff_Overtime_Hrs",Pivots!$M$3) -> 21025.4
B16: Patient Across Department
B17: Monthly Revenue
B18: Departmental Revenue
B19: Age Group By Appointment
B20: Clinical Status By Appointment

Sheet Patient_Data
A1: Patient_ID | B1: Month | C1: Short_Month | D1: Month_Num | E1: Admission_Date | F1: Date_Year | G1: Patient_Name | H1: Facility_Name | I1: Gender | J1: Age | K1: Clinical_Status | L1: CareStage | M1: Medical_Department | N1: MD_Short | O1: Patient_Bill | P1: Operational_Cost | Q1: Staff_Overtime_Hrs | R1: Risk_Tier | S1: Age_Group_Class
A2: NHM-2024-102404 | B2: =TEXT(Patient_Data!$E2,"mmmm") -> April | C2: =LEFT(B2,3) -> Apr | D2: =MONTH(Patient_Data!$E2) -> 4 | E2: 45395 | F2: =TEXT(Patient_Data[[#This Row],[Admission_Date]],"YYYY") -> 2024 | G2: Albert King | H2: NovaHealth Chicago Medical Center | I2: Male | J2: 30 | K2: Discharged | L2: 1 | M2: Neurology | N2: =IF(M2="Cardiology","Cardio",IF(M2="Intensive Care Unit","ICU",IF(M2="Neurology","Neuro",IF(M2="Emergency Room","ER",IF(M2="Pediatrics","PD",IF(M2="Surgery","Surgery",IF(M2="General Medicine","GM",IF(M2="Orthopedics","Ortho","")))))))) -> Neuro | O2: 9382.46 | P2: 6022.37 | Q2: 2.2 | R2: =IF(Patient_Data!$L2<2,"Low Risk",IF(Patient_Data!$L2<4,"Moderate Risk","High Risk")) -> Low Risk | S2: =IF(Patient_Data[[#This Row],[Age]]<=18,"Pediatric",IF(Patient_Data[[#This Row],[Age]]<=64,"Adult","Geriatric")) -> Adult
A3: NHM-2026-102164 | B3: =TEXT(Patient_Data!$E3,"mmmm") -> March | C3: =LEFT(B3,3) -> Mar | D3: =MONTH(Patient_Data!$E3) -> 3 | E3: 45730 | F3: =TEXT(Patient_Data[[#This Row],[Admission_Date]],"YYYY") -> 2025 | G3: Cynthia Clark | H3: NovaHealth Lakeside Medical Center | I3: Female | J3: 48 | K3: Discharged | L3: 1 | M3: Cardiology | N3: =IF(M3="Cardiology","Cardio",IF(M3="Intensive Care Unit","ICU",IF(M3="Neurology","Neuro",IF(M3="Emergency Room","ER",IF(M3="Pediatrics","PD",IF(M3="Surgery","Surgery",IF(M3="General Medicine","GM",IF(M3="Orthopedics","Ortho","")))))))) -> Cardio | O3: 8292.65 | P3: 5584.88 | Q3: 3.6 | R3: =IF(Patient_Data!$L3<2,"Low Risk",IF(Patient_Data!$L3<4,"Moderate Risk","High Risk")) -> Low Risk | S3: =IF(Patient_Data[[#This Row],[Age]]<=18,"Pediatric",IF(Patient_Data[[#This Row],[Age]]<=64,"Adult","Geriatric")) -> Adult
A4: NHM-2023-100823 | B4: =TEXT(Patient_Data!$E4,"mmmm") -> March | C4: =LEFT(B4,3) -> Mar | D4: =MONTH(Patient_Data!$E4) -> 3 | E4: 45376 | F4: =TEXT(Patient_Data[[#This Row],[Admission_Date]],"YYYY") -> 2024 | G4: Michelle Graham | H4: NovaHealth Chicago Medical Center | I4: Female | J4: 28 | K4: Discharged | L4: 2 | M4: General Medicine | N4: =IF(M4="Cardiology","Cardio",IF(M4="Intensive Care Unit","ICU",IF(M4="Neurology","Neuro",IF(M4="Emergency Room","ER",IF(M4="Pediatrics","PD",IF(M4="Surgery","Surgery",IF(M4="General Medicine","GM",IF(M4="Orthopedics","Ortho","")))))))) -> GM | O4: 4743.5 | P4: 3381.25 | Q4: 7.6 | R4: =IF(Patient_Data!$L4<2,"Low Risk",IF(Patient_Data!$L4<4,"Moderate Risk","High Risk")) -> Moderate Risk | S4: =IF(Patient_Data[[#This Row],[Age]]<=18,"Pediatric",IF(Patient_Data[[#This Row],[Age]]<=64,"Adult","Geriatric")) -> Adult
A5: NHM-2023-102060 | B5: =TEXT(Patient_Data!$E5,"mmmm") -> February | C5: =LEFT(B5,3) -> Feb | D5: =MONTH(Patient_Data!$E5) -> 2 | E5: 45345 | F5: =TEXT(Patient_Data[[#This Row],[Admission_Date]],"YYYY") -> 2024 | G5: Amy Hill | H5: NovaHealth Lakeshore Regional Center | I5: Female | J5: 70 | K5: Discharged | L5: 2 | M5: Cardiology | N5: =IF(M5="Cardiology","Cardio",IF(M5="Intensive Care Unit","ICU",IF(M5="Neurology","Neuro",IF(M5="Emergency Room","ER",IF(M5="Pediatrics","PD",IF(M5="Surgery","Surgery",IF(M5="General Medicine","GM",IF(M5="Orthopedics","Ortho","")))))))) -> Cardio | O5: 7138.49 | P5: 5267.1 | Q5: 7 | R5: =IF(Patient_Data!$L5<2,"Low Risk",IF(Patient_Data!$L5<4,"Moderate Risk","High Risk")) -> Moderate Risk | S5: =IF(Patient_Data[[#This Row],[Age]]<=18,"Pediatric",IF(Patient_Data[[#This Row],[Age]]<=64,"Adult","Geriatric")) -> Geriatric
A6: NHM-2025-101899 | B6: =TEXT(Patient_Data!$E6,"mmmm") -> January | C6: =LEFT(B6,3) -> Jan | D6: =MONTH(Patient_Data!$E6) -> 1 | E6: 46031 | F6: =TEXT(Patient_Data[[#This Row],[Admission_Date]],"YYYY") -> 2026 | G6: Evelyn Woods | H6: NovaHealth Chicago Medical Center | I6: Male | J6: 79 | K6: Readmitted | L6: 4 | M6: Orthopedics | N6: =IF(M6="Cardiology","Cardio",IF(M6="Intensive Care Unit","ICU",IF(M6="Neurology","Neuro",IF(M6="Emergency Room","ER",IF(M6="Pediatrics","PD",IF(M6="Surgery","Surgery",IF(M6="General Medicine","GM",IF(M6="Orthopedics","Ortho","")))))))) -> Ortho | O6: 9221.73 | P6: 7079.71 | Q6: 8.9 | R6: =IF(Patient_Data!$L6<2,"Low Risk",IF(Patient_Data!$L6<4,"Moderate Risk","High Risk")) -> High Risk | S6: =IF(Patient_Data[[#This Row],[Age]]<=18,"Pediatric",IF(Patient_Data[[#This Row],[Age]]<=64,"Adult","Geriatric")) -> Geriatric
A7: NHM-2026-101384 | B7: =TEXT(Patient_Data!$E7,"mmmm") -> November | C7: =LEFT(B7,3) -> Nov | D7: =MONTH(Patient_Data!$E7) -> 11 | E7: 45232 | F7: =TEXT(Patient_Data[[#This Row],[Admission_Date]],"YYYY") -> 2023 | G7: Michelle Martinez | H7: NovaHealth Midtown Medical Center | I7: Male | J7: 59 | K7: Readmitted | L7: 3 | M7: Intensive Care Unit | N7: =IF(M7="Cardiology","Cardio",IF(M7="Intensive Care Unit","ICU",IF(M7="Neurology","Neuro",IF(M7="Emergency Room","ER",IF(M7="Pediatrics","PD",IF(M7="Surgery","Surgery",IF(M7="General Medicine","GM",IF(M7="Orthopedics","Ortho","")))))))) -> ICU | O7: 18870.98 | P7: 11079.57 | Q7: 16.8 | R7: =IF(Patient_Data!$L7<2,"Low Risk",IF(Patient_Data!$L7<4,"Moderate Risk","High Risk")) -> Moderate Risk | S7: =IF(Patient_Data[[#This Row],[Age]]<=18,"Pediatric",IF(Patient_Data[[#This Row],[Age]]<=64,"Adult","Geriatric")) -> Adult
A8: NHM-2023-102093 | B8: =TEXT(Patient_Data!$E8,"mmmm") -> October | C8: =LEFT(B8,3) -> Oct | D8: =MONTH(Patient_Data!$E8) -> 10 | E8: 45228 | F8: =TEXT(Patient_Data[[#This Row],[Admission_Date]],"YYYY") -> 2023 | G8: Austin Webb | H8: NovaHealth Greenfield Clinic | I8: Female | J8: 91 | K8: In-Patient Care | L8: 5 | M8: Intensive Care Unit | N8: =IF(M8="Cardiology","Cardio",IF(M8="Intensive Care Unit","ICU",IF(M8="Neurology","Neuro",IF(M8="Emergency Room","ER",IF(M8="Pediatrics","PD",IF(M8="Surgery","Surgery",IF(M8="General Medicine","GM",IF(M8="Orthopedics","Ortho","")))))))) -> ICU | O8: 22963.46 | P8: 14094.11 | Q8: 10.8 | R8: =IF(Patient_Data!$L8<2,"Low Risk",IF(Patient_Data!$L8<4,"Moderate Risk","High Risk")) -> High Risk | S8: =IF(Patient_Data[[#This Row],[Age]]<=18,"Pediatric",IF(Patient_Data[[#This Row],[Age]]<=64,"Adult","Geriatric")) -> Geriatric
A9: NHM-2023-100762 | B9: =TEXT(Patient_Data!$E9,"mmmm") -> December | C9: =LEFT(B9,3) -> Dec | D9: =MONTH(Patient_Data!$E9) -> 12 | E9: 45643 | F9: =TEXT(Patient_Data[[#This Row],[Admission_Date]],"YYYY") -> 2024 | G9: Jacob Lee | H9: Nova Health Chicago Medical Center | I9: Male | J9: 38 | K9: Discharged | L9: 1 | M9: Cardiology | N9: =IF(M9="Cardiology","Cardio",IF(M9="Intensive Care Unit","ICU",IF(M9="Neurology","Neuro",IF(M9="Emergency Room","ER",IF(M9="Pediatrics","PD",IF(M9="Surgery","Surgery",IF(M9="General Medicine","GM",IF(M9="Orthopedics","Ortho","")))))))) -> Cardio | O9: 5217.55 | P9: 3364.83 | Q9: 3.2 | R9: =IF(Patient_Data!$L9<2,"Low Risk",IF(Patient_Data!$L9<4,"Moderate Risk","High Risk")) -> Low Risk | S9: =IF(Patient_Data[[#This Row],[Age]]<=18,"Pediatric",IF(Patient_Data[[#This Row],[Age]]<=64,"Adult","Geriatric")) -> Adult
A10: NHM-2026-102456 | B10: =TEXT(Patient_Data!$E10,"mmmm") -> October | C10: =LEFT(B10,3) -> Oct | D10: =MONTH(Patient_Data!$E10) -> 10 | E10: 45574 | F10: =TEXT(Patient_Data[[#This Row],[Admission_Date]],"YYYY") -> 2024 | G10: Theresa Ross | H10: NovaHealth Lakeside Medical Center | I10: Female | J10: 53 | K10: Discharged | L10: 1 | M10: Orthopedics | N10: =IF(M10="Cardiology","Cardio",IF(M10="Intensive Care Unit","ICU",IF(M10="Neurology","Neuro",IF(M10="Emergency Room","ER",IF(M10="Pediatrics","PD",IF(M10="Surgery","Surgery",IF(M10="General Medicine","GM",IF(M10="Orthopedics","Ortho","")))))))) -> Ortho | O10: 5182.32 | P10: 3506.55 | Q10: 4.3 | R10: =IF(Patient_Data!$L10<2,"Low Risk",IF(Patient_Data!$L10<4,"Moderate Risk","High Risk")) -> Low Risk | S10: =IF(Patient_Data[[#This Row],[Age]]<=18,"Pediatric",IF(Patient_Data[[#This Row],[Age]]<=64,"Adult","Geriatric")) -> Adult
A11: NHM-2025-100770 | B11: =TEXT(Patient_Data!$E11,"mmmm") -> March | C11: =LEFT(B11,3) -> Mar | D11: =MONTH(Patient_Data!$E11) -> 3 | E11: 45736 | F11: =TEXT(Patient_Data[[#This Row],[Admission_Date]],"YYYY") -> 2025 | G11: James Castillo | H11: NovaHealth Chicago Medical Center | I11: Male | J11: 35 | K11: Discharged | L11: 1 | M11: General Medicine | N11: =IF(M11="Cardiology","Cardio",IF(M11="Intensive Care Unit","ICU",IF(M11="Neurology","Neuro",IF(M11="Emergency Room","ER",IF(M11="Pediatrics","PD",IF(M11="Surgery","Surgery",IF(M11="General Medicine","GM",IF(M11="Orthopedics","Ortho","")))))))) -> GM | O11: 2381.2 | P11: 1702.84 | Q11: 4.5 | R11: =IF(Patient_Data!$L11<2,"Low Risk",IF(Patient_Data!$L11<4,"Moderate Risk","High Risk")) -> Low Risk | S11: =IF(Patient_Data[[#This Row],[Age]]<=18,"Pediatric",IF(Patient_Data[[#This Row],[Age]]<=64,"Adult","Geriatric")) -> Adult
A12: NHM-2025-101456 | B12: =TEXT(Patient_Data!$E12,"mmmm") -> September | C12: =LEFT(B12,3) -> Sep | D12: =MONTH(Patient_Data!$E12) -> 9 | E12: 45180 | F12: =TEXT(Patient_Data[[#This Row],[Admission_Date]],"YYYY") -> 2023 | G12: Sarah Diaz | H12: Nova Health Lakeshore Regional Center | I12: Male | J12: 42 | K12: Discharged | L12: 1 | M12: Neurology | N12: =IF(M12="Cardiology","Cardio",IF(M12="Intensive Care Unit","ICU",IF(M12="Neurology","Neuro",IF(M12="Emergency Room","ER",IF(M12="Pediatrics","PD",IF(M12="Surgery","Surgery",IF(M12="General Medicine","GM",IF(M12="Orthopedics","Ortho","")))))))) -> Neuro | O12: 8544.19 | P12: 6299.66 | Q12: 7.8 | R12: =IF(Patient_Data!$L12<2,"Low Risk",IF(Patient_Data!$L12<4,"Moderate Risk","High Risk")) -> Low Risk | S12: =IF(Patient_Data[[#This Row],[Age]]<=18,"Pediatric",IF(Patient_Data[[#This Row],[Age]]<=64,"Adult","Geriatric")) -> Adult
A13: NHM-2023-102375 | B13: =TEXT(Patient_Data!$E13,"mmmm") -> July | C13: =LEFT(B13,3) -> Jul | D13: =MONTH(Patient_Data!$E13) -> 7 | E13: 45863 | F13: =TEXT(Patient_Data[[#This Row],[Admission_Date]],"YYYY") -> 2025 | G13: Debra Brooks | H13: NovaHealth Chicago Medical Center | I13: Male | J13: 44 | K13: Discharged | L13: 2 | M13: Neurology | N13: =IF(M13="Cardiology","Cardio",IF(M13="Intensive Care Unit","ICU",IF(M13="Neurology","Neuro",IF(M13="Emergency Room","ER",IF(M13="Pediatrics","PD",IF(M13="Surgery","Surgery",IF(M13="General Medicine","GM",IF(M13="Orthopedics","Ortho","")))))))) -> Neuro | O13: 8917.69 | P13: 6828.64 | Q13: 6.4 | R13: =IF(Patient_Data!$L13<2,"Low Risk",IF(Patient_Data!$L13<4,"Moderate Risk","High Risk")) -> Moderate Risk | S13: =IF(Patient_Data[[#This Row],[Age]]<=18,"Pediatric",IF(Patient_Data[[#This Row],[Age]]<=64,"Adult","Geriatric")) -> Adult
... A95: NHM-2024-100495 | B95: =TEXT(Patient_Data!$E95,"mmmm") -> December | C95: =LEFT(B95,3) -> Dec | D95: =MONTH(Patient_Data!$E95) -> 12 | E95: 45627 | F95: =TEXT(Patient_Data[[#This Row],[Admission_Date]],"YYYY") -> 2024 | G95: Ann Gomez | H95: NovaHealth Oakridge Community Hospital | I95: Female | J95: 65 | K95: Readmitted | L95: 4 | M95: Surgery | N95: =IF(M95="Cardiology","Cardio",IF(M95="Intensive Care Unit","ICU",IF(M95="Neurology","Neuro",IF(M95="Emergency Room","ER",IF(M95="Pediatrics","PD",IF(M95="Surgery","Surgery",IF(M95="General Medicine","GM",IF(M95="Orthopedics","Ortho","")))))))) -> Surgery | O95: 11963.03 | P95: 8433.32 | Q95: 7.4 | R95: =IF(Patient_Data!$L95<2,"Low Risk",IF(Patient_Data!$L95<4,"Moderate Risk","High Risk")) -> High Risk | S95: =IF(Patient_Data[[#This Row],[Age]]<=18,"Pediatric",IF(Patient_Data[[#This Row],[Age]]<=64,"Adult","Geriatric")) -> Geriatric
A96: NHM-2026-100017 | B96: =TEXT(Patient_Data!$E96,"mmmm") -> October | C96: =LEFT(B96,3) -> Oct | D96: =MONTH(Patient_Data!$E96) -> 10 | E96: 45210 | F96: =TEXT(Patient_Data[[#This Row],[Admission_Date]],"YYYY") -> 2023 | G96: Joe Freeman | H96: NovaHealth Chicago Medical Center | I96: Female | J96: 84 | K96: In-Patient Care | L96: 4 | M96: Neurology | N96: =IF(M96="Cardiology","Cardio",IF(M96="Intensive Care Unit","ICU",IF(M96="Neurology","Neuro",IF(M96="Emergency Room","ER",IF(M96="Pediatrics","PD",IF(M96="Surgery","Surgery",IF(M96="General Medicine","GM",IF(M96="Orthopedics","Ortho","")))))))) -> Neuro | O96: 12745.26 | P96: 9304.04 | R96: =IF(Patient_Data!$L96<2,"Low Risk",IF(Patient_Data!$L96<4,"Moderate Risk","High Risk")) -> High Risk | S96: =IF(Patient_Data[[#This Row],[Age]]<=18,"Pediatric",IF(Patient_Data[[#This Row],[Age]]<=64,"Adult","Geriatric")) -> Geriatric
A97: NHM-2025-102343 | B97: =TEXT(Patient_Data!$E97,"mmmm") -> December | C97: =LEFT(B97,3) -> Dec | D97: =MONTH(Patient_Data!$E97) -> 12 | E97: 45638 | F97: =TEXT(Patient_Data[[#This Row],[Admission_Date]],"YYYY") -> 2024 | G97: Elizabeth Reed | H97: NovaHealth Chicago Medical Center | I97: Male | J97: 57 | K97: Readmitted | L97: 4 | M97: Intensive Care Unit | N97: =IF(M97="Cardiology","Cardio",IF(M97="Intensive Care Unit","ICU",IF(M97="Neurology","Neuro",IF(M97="Emergency Room","ER",IF(M97="Pediatrics","PD",IF(M97="Surgery","Surgery",IF(M97="General Medicine","GM",IF(M97="Orthopedics","Ortho","")))))))) -> ICU | O97: 14707.38 | P97: 11288.81 | Q97: 13.9 | R97: =IF(Patient_Data!$L97<2,"Low Risk",IF(Patient_Data!$L97<4,"Moderate Risk","High Risk")) -> High Risk | S97: =IF(Patient_Data[[#This Row],[Age]]<=18,"Pediatric",IF(Patient_Data[[#This Row],[Age]]<=64,"Adult","Geriatric")) -> Adult
A98: NHM-2026-100012 | B98: =TEXT(Patient_Data!$E98,"mmmm") -> November | C98: =LEFT(B98,3) -> Nov | D98: =MONTH(Patient_Data!$E98) -> 11 | E98: 45618 | F98: =TEXT(Patient_Data[[#This Row],[Admission_Date]],"YYYY") -> 2024 | G98: Jessica Castillo | H98: NovaHealth Greenfield Clinic | I98: Female | J98: 73 | K98: In-Patient Care | L98: 5 | M98: Intensive Care Unit | N98: =IF(M98="Cardiology","Cardio",IF(M98="Intensive Care Unit","ICU",IF(M98="Neurology","Neuro",IF(M98="Emergency Room","ER",IF(M98="Pediatrics","PD",IF(M98="Surgery","Surgery",IF(M98="General Medicine","GM",IF(M98="Orthopedics","Ortho","")))))))) -> ICU | O98: 14836.43 | P98: 8605.13 | R98: =IF(Patient_Data!$L98<2,"Low Risk",IF(Patient_Data!$L98<4,"Moderate Risk","High Risk")) -> High Risk | S98: =IF(Patient_Data[[#This Row],[Age]]<=18,"Pediatric",IF(Patient_Data[[#This Row],[Age]]<=64,"Adult","Geriatric")) -> Geriatric
A99: NHM-2023-100789 | B99: =TEXT(Patient_Data!$E99,"mmmm") -> September | C99: =LEFT(B99,3) -> Sep | D99: =MONTH(Patient_Data!$E99) -> 9 | E99: 45181 | F99: =TEXT(Patient_Data[[#This Row],[Admission_Date]],"YYYY") -> 2023 | G99: Linda Cooper | H99: NovaHealth Chicago Medical Center | I99: Female | J99: 90 | K99: In-Patient Care | L99: 4 | M99: Intensive Care Unit | N99: =IF(M99="Cardiology","Cardio",IF(M99="Intensive Care Unit","ICU",IF(M99="Neurology","Neuro",IF(M99="Emergency Room","ER",IF(M99="Pediatrics","PD",IF(M99="Surgery","Surgery",IF(M99="General Medicine","GM",IF(M99="Orthopedics","Ortho","")))))))) -> ICU | O99: 18045.56 | P99: 11146.99 | Q99: 17.4 | R99: =IF(Patient_Data!$L99<2,"Low Risk",IF(Patient_Data!$L99<4,"Moderate Risk","High Risk")) -> High Risk | S99: =IF(Patient_Data[[#This Row],[Age]]<=18,"Pediatric",IF(Patient_Data[[#This Row],[Age]]<=64,"Adult","Geriatric")) -> Geriatric
A100: NHM-2024-102113 | B100: =TEXT(Patient_Data!$E100,"mmmm") -> December | C100: =LEFT(B100,3) -> Dec | D100: =MONTH(Patient_Data!$E100) -> 12 | E100: 45287 | F100: =TEXT(Patient_Data[[#This Row],[Admission_Date]],"YYYY") -> 2023 | G100: Daniel Ford | H100: NovaHealth Northside Hospital | I100: Female | J100: 10 | K100: In-Patient Care | L100: 3 | M100: Pediatrics | N100: =IF(M100="Cardiology","Cardio",IF(M100="Intensive Care Unit","ICU",IF(M100="Neurology","Neuro",IF(M100="Emergency Room","ER",IF(M100="Pediatrics","PD",IF(M100="Surgery","Surgery",IF(M100="General Medicine","GM",IF(M100="Orthopedics","Ortho","")))))))) -> PD | O100: 3084.79 | P100: 1997.47 | Q100: 2.9 | R100: =IF(Patient_Data!$L100<2,"Low Risk",IF(Patient_Data!$L100<4,"Moderate Risk","High Risk")) -> Moderate Risk | S100: =IF(Patient_Data[[#This Row],[Age]]<=18,"Pediatric",IF(Patient_Data[[#This Row],[Age]]<=64,"Adult","Geriatric")) -> Pediatric
A101: NHM-2026-101321 | B101: =TEXT(Patient_Data!$E101,"mmmm") -> December | C101: =LEFT(B101,3) -> Dec | D101: =MONTH(Patient_Data!$E101) -> 12 | E101: 45635 | F101: =TEXT(Patient_Data[[#This Row],[Admission_Date]],"YYYY") -> 2024 | G101: Deborah Thompson | H101: NovaHealth Northside Hospital | I101: Male | J101: 57 | K101: Discharged | L101: 2 | M101: General Medicine | N101: =IF(M101="Cardiology","Cardio",IF(M101="Intensive Care Unit","ICU",IF(M101="Neurology","Neuro",IF(M101="Emergency Room","ER",IF(M101="Pediatrics","PD",IF(M101="Surgery","Surgery",IF(M101="General Medicine","GM",IF(M101="Orthopedics","Ortho","")))))))) -> GM | O101: 2639.94 | P101: 1831.96 | Q101: 7.9 | R101: =IF(Patient_Data!$L101<2,"Low Risk",IF(Patient_Data!$L101<4,"Moderate Risk","High Risk")) -> Moderate Risk | S101: =IF(Patient_Data[[#This Row],[Age]]<=18,"Pediatric",IF(Patient_Data[[#This Row],[Age]]<=64,"Adult","Geriatric")) -> Adult
A102: NHM-2025-100635 | B102: =TEXT(Patient_Data!$E102,"mmmm") -> July | C102: =LEFT(B102,3) -> Jul | D102: =MONTH(Patient_Data!$E102) -> 7 | E102: 45843 | F102: =TEXT(Patient_Data[[#This Row],[Admission_Date]],"YYYY") -> 2025 | G102: Kyle Hughes | H102: NovaHealth Greenfield Clinic | I102: Female | J102: 71 | K102: Readmitted | L102: 2 | M102: General Medicine | N102: =IF(M102="Cardiology","Cardio",IF(M102="Intensive Care Unit","ICU",IF(M102="Neurology","Neuro",IF(M102="Emergency Room","ER",IF(M102="Pediatrics","PD",IF(M102="Surgery","Surgery",IF(M102="General Medicine","GM",IF(M102="Orthopedics","Ortho","")))))))) -> GM | O102: 1892.81 | P102: 1400.97 | Q102: 9.5 | R102: =IF(Patient_Data!$L102<2,"Low Risk",IF(Patient_Data!$L102<4,"Moderate Risk","High Risk")) -> Moderate Risk | S102: =IF(Patient_Data[[#This Row],[Age]]<=18,"Pediatric",IF(Patient_Data[[#This Row],[Age]]<=64,"Adult","Geriatric")) -> Geriatric
A103: NHM-2023-100382 | B103: =TEXT(Patient_Data!$E103,"mmmm") -> May | C103: =LEFT(B103,3) -> May | D103: =MONTH(Patient_Data!$E103) -> 5 | E103: 46161 | F103: =TEXT(Patient_Data[[#This Row],[Admission_Date]],"YYYY") -> 2026 | G103: Brandon Martinez | H103: NovaHealth Greenfield Clinic | I103: Female | J103: 57 | K103: Readmitted | L103: 4 | M103: Surgery | N103: =IF(M103="Cardiology","Cardio",IF(M103="Intensive Care Unit","ICU",IF(M103="Neurology","Neuro",IF(M103="Emergency Room","ER",IF(M103="Pediatrics","PD",IF(M103="Surgery","Surgery",IF(M103="General Medicine","GM",IF(M103="Orthopedics","Ortho","")))))))) -> Surgery | O103: 18363.29 | P103: 13454 | Q103: 6.1 | R103: =IF(Patient_Data!$L103<2,"Low Risk",IF(Patient_Data!$L103<4,"Moderate Risk","High Risk")) -> High Risk | S103: =IF(Patient_Data[[#This Row],[Age]]<=18,"Pediatric",IF(Patient_Data[[#This Row],[Age]]<=64,"Adult","Geriatric")) -> Adult
A104: NHM-2026-101549 | B104: =TEXT(Patient_Data!$E104,"mmmm") -> April | C104: =LEFT(B104,3) -> Apr | D104: =MONTH(Patient_Data!$E104) -> 4 | E104: 46135 | F104: =TEXT(Patient_Data[[#This Row],[Admission_Date]],"YYYY") -> 2026 | G104: Rachel Marshall | H104: NovaHealth Greenfield Clinic | I104: Female | J104: 79 | K104: Discharged | L104: 3 | M104: Neurology | N104: =IF(M104="Cardiology","Cardio",IF(M104="Intensive Care Unit","ICU",IF(M104="Neurology","Neuro",IF(M104="Emergency Room","ER",IF(M104="Pediatrics","PD",IF(M104="Surgery","Surgery",IF(M104="General Medicine","GM",IF(M104="Orthopedics","Ortho","")))))))) -> Neuro | O104: 10144.1 | P104: 7798.32 | Q104: 11.1 | R104: =IF(Patient_Data!$L104<2,"Low Risk",IF(Patient_Data!$L104<4,"Moderate Risk","High Risk")) -> Moderate Risk | S104: =IF(Patient_Data[[#This Row],[Age]]<=18,"Pediatric",IF(Patient_Data[[#This Row],[Age]]<=64,"Adult","Geriatric")) -> Geriatric
A105: NHM-2025-102422 | B105: =TEXT(Patient_Data!$E105,"mmmm") -> January | C105: =LEFT(B105,3) -> Jan | D105: =MONTH(Patient_Data!$E105) -> 1 | E105: 45664 | F105: =TEXT(Patient_Data[[#This Row],[Admission_Date]],"YYYY") -> 2025 | G105: Diane Reynolds | H105: NovaHealth Northside Hospital | I105: Female | J105: 72 | K105: Readmitted | L105: 5 | M105: Intensive Care Unit | N105: =IF(M105="Cardiology","Cardio",IF(M105="Intensive Care Unit","ICU",IF(M105="Neurology","Neuro",IF(M105="Emergency Room","ER",IF(M105="Pediatrics","PD",IF(M105="Surgery","Surgery",IF(M105="General Medicine","GM",IF(M105="Orthopedics","Ortho","")))))))) -> ICU | O105: 11452.59 | P105: 6769.7 | Q105: 15.9 | R105: =IF(Patient_Data!$L105<2,"Low Risk",IF(Patient_Data!$L105<4,"Moderate Risk","High Risk")) -> High Risk | S105: =IF(Patient_Data[[#This Row],[Age]]<=18,"Pediatric",IF(Patient_Data[[#This Row],[Age]]<=64,"Adult","Geriatric")) -> Geriatric
A106: NHM-2023-101918 | B106: =TEXT(Patient_Data!$E106,"mmmm") -> April | C106: =LEFT(B106,3) -> Apr | D106: =MONTH(Patient_Data!$E106) -> 4 | E106: 46135 | F106: =TEXT(Patient_Data[[#This Row],[Admission_Date]],"YYYY") -> 2026 | G106: Joe Myers | H106: NovaHealth Chicago Medical Center | I106: Female | J106: 80 | K106: In-Patient Care | L106: 4 | M106: Cardiology | N106: =IF(M106="Cardiology","Cardio",IF(M106="Intensive Care Unit","ICU",IF(M106="Neurology","Neuro",IF(M106="Emergency Room","ER",IF(M106="Pediatrics","PD",IF(M106="Surgery","Surgery",IF(M106="General Medicine","GM",IF(M106="Orthopedics","Ortho","")))))))) -> Cardio | O106: 8820.6 | P106: 5449.37 | Q106: 8.6 | R106: =IF(Patient_Data!$L106<2,"Low Risk",IF(Patient_Data!$L106<4,"Moderate Risk","High Risk")) -> High Risk | S106: =IF(Patient_Data[[#This Row],[Age]]<=18,"Pediatric",IF(Patient_Data[[#This Row],[Age]]<=64,"Adult","Geriatric")) -> Geriatric
A107: NHM-2024-102496 | B107: =TEXT(Patient_Data!$E107,"mmmm") -> December | C107: =LEFT(B107,3) -> Dec | D107: =MONTH(Patient_Data!$E107) -> 12 | E107: 46000 | F107: =TEXT(Patient_Data[[#This Row],[Admission_Date]],"YYYY") -> 2025 | G107: James Jenkins | H107: NovaHealth Midtown Medical Center | I107: Male | J107: 29 | K107: Discharged | L107: 1 | M107: Neurology | N107: =IF(M107="Cardiology","Cardio",IF(M107="Intensive Care Unit","ICU",IF(M107="Neurology","Neuro",IF(M107="Emergency Room","ER",IF(M107="Pediatrics","PD",IF(M107="Surgery","Surgery",IF(M107="General Medicine","GM",IF(M107="Orthopedics","Ortho","")))))))) -> Neuro | O107: 5500.22 | P107: 3552.94 | Q107: 4.1 | R107: =IF(Patient_Data!$L107<2,"Low Risk",IF(Patient_Data!$L107<4,"Moderate Risk","High Risk")) -> Low Risk | S107: =IF(Patient_Data[[#This Row],[Age]]<=18,"Pediatric",IF(Patient_Data[[#This Row],[Age]]<=64,"Adult","Geriatric")) -> Adult
A108: NHM-2024-102468 | B108: =TEXT(Patient_Data!$E108,"mmmm") -> September | C108: =LEFT(B108,3) -> Sep | D108: =MONTH(Patient_Data!$E108) -> 9 | E108: 45556 | F108: =TEXT(Patient_Data[[#This Row],[Admission_Date]],"YYYY") -> 2024 | G108: Ralph Miller | H108: NovaHealth Chicago Medical Center | I108: Female | J108: 90 | K108: In-Patient Care | L108: 4 | M108: Intensive Care Unit | N108: =IF(M108="Cardiology","Cardio",IF(M108="Intensive Care Unit","ICU",IF(M108="Neurology","Neuro",IF(M108="Emergency Room","ER",IF(M108="Pediatrics","PD",IF(M108="Surgery","Surgery",IF(M108="General Medicine","GM",IF(M108="Orthopedics","Ortho","")))))))) -> ICU | O108: 11284.32 | P108: 7560.49 | R108: =IF(Patient_Data!$L108<2,"Low Risk",IF(Patient_Data!$L108<4,"Moderate Risk","High Risk")) -> High Risk | S108: =IF(Patient_Data[[#This Row],[Age]]<=18,"Pediatric",IF(Patient_Data[[#This Row],[Age]]<=64,"Adult","Geriatric")) -> Geriatric
A109: NHM-2025-100756 | B109: =TEXT(Patient_Data!$E109,"mmmm") -> January | C109: =LEFT(B109,3) -> Jan | D109: =MONTH(Patient_Data!$E109) -> 1 | E109: 46049 | F109: =TEXT(Patient_Data[[#This Row],[Admission_Date]],"YYYY") -> 2026 | G109: Bruce Diaz | H109: NovaHealth Chicago Medical Center | I109: Female | J109: 52 | K109: Discharged | L109: 1 | M109: Orthopedics | N109: =IF(M109="Cardiology","Cardio",IF(M109="Intensive Care Unit","ICU",IF(M109="Neurology","Neuro",IF(M109="Emergency Room","ER",IF(M109="Pediatrics","PD",IF(M109="Surgery","Surgery",IF(M109="General Medicine","GM",IF(M109="Orthopedics","Ortho","")))))))) -> Ortho | O109: 7849.84 | P109: 5561.29 | Q109: 8.3 | R109: =IF(Patient_Data!$L109<2,"Low Risk",IF(Patient_Data!$L109<4,"Moderate Risk","High Risk")) -> Low Risk | S109: =IF(Patient_Data[[#This Row],[Age]]<=18,"Pediatric",IF(Patient_Data[[#This Row],[Age]]<=64,"Adult","Geriatric")) -> Adult
A110: NHM-2024-100952 | B110: =TEXT(Patient_Data!$E110,"mmmm") -> March | C110: =LEFT(B110,3) -> Mar | D110: =MONTH(Patient_Data!$E110) -> 3 | E110: 45368 | F110: =TEXT(Patient_Data[[#This Row],[Admission_Date]],"YYYY") -> 2024 | G110: Grace Alexander | H110: NovaHealth Northside Hospital | I110: Male | J110: 32 | K110: In-Patient Care | L110: 4 | M110: Surgery | N110: =IF(M110="Cardiology","Cardio",IF(M110="Intensive Care Unit","ICU",IF(M110="Neurology","Neuro",IF(M110="Emergency Room","ER",IF(M110="Pediatrics","PD",IF(M110="Surgery","Surgery",IF(M110="General Medicine","GM",IF(M110="Orthopedics","Ortho","")))))))) -> Surgery | O110: 22910.18 | P110: 16755.63 | Q110: 3.9 | R110: =IF(Patient_Data!$L110<2,"Low Risk",IF(Patient_Data!$L110<4,"Moderate Risk","High Risk")) -> High Risk | S110: =IF(Patient_Data[[#This Row],[Age]]<=18,"Pediatric",IF(Patient_Data[[#This Row],[Age]]<=64,"Adult","Geriatric")) -> Adult
A111: NHM-2023-101702 | B111: =TEXT(Patient_Data!$E111,"mmmm") -> July | C111: =LEFT(B111,3) -> Jul | D111: =MONTH(Patient_Data!$E111) -> 7 | E111: 45861 | F111: =TEXT(Patient_Data[[#This Row],[Admission_Date]],"YYYY") -> 2025 | G111: Juan Patel | H111: NovaHealth Lakeside Medical Center | I111: Male | J111: 80 | K111: Readmitted | L111: 3 | M111: Surgery | N111: =IF(M111="Cardiology","Cardio",IF(M111="Intensive Care Unit","ICU",IF(M111="Neurology","Neuro",IF(M111="Emergency Room","ER",IF(M111="Pediatrics","PD",IF(M111="Surgery","Surgery",IF(M111="General Medicine","GM",IF(M111="Orthopedics","Ortho","")))))))) -> Surgery | O111: 14981.93 | P111: 11468.67 | Q111: 10.3 | R111: =IF(Patient_Data!$L111<2,"Low Risk",IF(Patient_Data!$L111<4,"Moderate Risk","High Risk")) -> Moderate Risk | S111: =IF(Patient_Data[[#This Row],[Age]]<=18,"Pediatric",IF(Patient_Data[[#This Row],[Age]]<=64,"Adult","Geriatric")) -> Geriatric
A112: NHM-2023-101430 | B112: =TEXT(Patient_Data!$E112,"mmmm") -> April | C112: =LEFT(B112,3) -> Apr | D112: =MONTH(Patient_Data!$E112) -> 4 | E112: 45390 | F112: =TEXT(Patient_Data[[#This Row],[Admission_Date]],"YYYY") -> 2024 | G112: Edward Coleman | H112: NovaHealth Metro General Hospital | I112: Female | J112: 81 | K112: In-Patient Care | L112: 4 | M112: Intensive Care Unit | N112: =IF(M112="Cardiology","Cardio",IF(M112="Intensive Care Unit","ICU",IF(M112="Neurology","Neuro",IF(M112="Emergency Room","ER",IF(M112="Pediatrics","PD",IF(M112="Surgery","Surgery",IF(M112="General Medicine","GM",IF(M112="Orthopedics","Ortho","")))))))) -> ICU | O112: 13603.14 | P112: 7961.02 | Q112: 8.9 | R112: =IF(Patient_Data!$L112<2,"Low Risk",IF(Patient_Data!$L112<4,"Moderate Risk","High Risk")) -> High Risk | S112: =IF(Patient_Data[[#This Row],[Age]]<=18,"Pediatric",IF(Patient_Data[[#This Row],[Age]]<=64,"Adult","Geriatric")) -> Geriatric
A113: NHM-2023-100623 | B113: =TEXT(Patient_Data!$E113,"mmmm") -> March | C113: =LEFT(B113,3) -> Mar | D113: =MONTH(Patient_Data!$E113) -> 3 | E113: 46085 | F113: =TEXT(Patient_Data[[#This Row],[Admission_Date]],"YYYY") -> 2026 | G113: Janice Crawford | H113: NovaHealth Chicago Medical Center | I113: Female | J113: 95 | K113: Discharged | L113: 4 | M113: Orthopedics | N113: =IF(M113="Cardiology","Cardio",IF(M113="Intensive Care Unit","ICU",IF(M113="Neurology","Neuro",IF(M113="Emergency Room","ER",IF(M113="Pediatrics","PD",IF(M113="Surgery","Surgery",IF(M113="General Medicine","GM",IF(M113="Orthopedics","Ortho","")))))))) -> Ortho | O113: 10262.95 | P113: 6300.4 | Q113: 5 | R113: =IF(Patient_Data!$L113<2,"Low Risk",IF(Patient_Data!$L113<4,"Moderate Risk","High Risk")) -> High Risk | S113: =IF(Patient_Data[[#This Row],[Age]]<=18,"Pediatric",IF(Patient_Data[[#This Row],[Age]]<=64,"Adult","Geriatric")) -> Geriatric
A114: NHM-2024-101884 | B114: =TEXT(Patient_Data!$E114,"mmmm") -> June | C114: =LEFT(B114,3) -> Jun | D114: =MONTH(Patient_Data!$E114) -> 6 | E114: 45454 | F114: =TEXT(Patient_Data[[#This Row],[Admission_Date]],"YYYY") -> 2024 | G114: Beverly Stevens | H114: NovaHealth River Valley Hospital | I114: Female | J114: 68 | K114: Discharged | L114: 1 | M114: Emergency Room | N114: =IF(M114="Cardiology","Cardio",IF(M114="Intensive Care Unit","ICU",IF(M114="Neurology","Neuro",IF(M114="Emergency Room","ER",IF(M114="Pediatrics","PD",IF(M114="Surgery","Surgery",IF(M114="General Medicine","GM",IF(M114="Orthopedics","Ortho","")))))))) -> ER | O114: 3646.44 | P114: 2456.92 | Q114: 15.4 | R114: =IF(Patient_Data!$L114<2,"Low Risk",IF(Patient_Data!$L114<4,"Moderate Risk","High Risk")) -> Low Risk | S114: =IF(Patient_Data[[#This Row],[Age]]<=18,"Pediatric",IF(Patient_Data[[#This Row],[Age]]<=64,"Adult","Geriatric")) -> Geriatric
A115: NHM-2024-100230 | B115: =TEXT(Patient_Data!$E115,"mmmm") -> January | C115: =LEFT(B115,3) -> Jan | D115: =MONTH(Patient_Data!$E115) -> 1 | E115: 46031 | F115: =TEXT(Patient_Data[[#This Row],[Admission_Date]],"YYYY") -> 2026 | G115: Catherine Russell | H115: NovaHealth Lakeside Medical Center | I115: Female | J115: 66 | K115: Readmitted | L115: 3 | M115: Emergency Room | N115: =IF(M115="Cardiology","Cardio",IF(M115="Intensive Care Unit","ICU",IF(M115="Neurology","Neuro",IF(M115="Emergency Room","ER",IF(M115="Pediatrics","PD",IF(M115="Surgery","Surgery",IF(M115="General Medicine","GM",IF(M115="Orthopedics","Ortho","")))))))) -> ER | O115: 6590.34 | P115: 4585.13 | Q115: 21.2 | R115: =IF(Patient_Data!$L115<2,"Low Risk",IF(Patient_Data!$L115<4,"Moderate Risk","High Risk")) -> Moderate Risk | S115: =IF(Patient_Data[[#This Row],[Age]]<=18,"Pediatric",IF(Patient_Data[[#This Row],[Age]]<=64,"Adult","Geriatric")) -> Geriatric
A116: NHM-2025-100947 | B116: =TEXT(Patient_Data!$E116,"mmmm") -> January | C116: =LEFT(B116,3) -> Jan | D116: =MONTH(Patient_Data!$E116) -> 1 | E116: 45678 | F116: =TEXT(Patient_Data[[#This Row],[Admission_Date]],"YYYY") -> 2025 | G116: Martha Hughes | H116: NovaHealth Chicago Medical Center | I116: Male | J116: 63 | K116: Discharged | L116: 2 | M116: General Medicine | N116: =IF(M116="Cardiology","Cardio",IF(M116="Intensive Care Unit","ICU",IF(M116="Neurology","Neuro",IF(M116="Emergency Room","ER",IF(M116="Pediatrics","PD",IF(M116="Surgery","Surgery",IF(M116="General Medicine","GM",IF(M116="Orthopedics","Ortho","")))))))) -> GM | O116: 3062.14 | P116: 2198.7 | Q116: 6.9 | R116: =IF(Patient_Data!$L116<2,"Low Risk",IF(Patient_Data!$L116<4,"Moderate Risk","High Risk")) -> Moderate Risk | S116: =IF(Patient_Data[[#This Row],[Age]]<=18,"Pediatric",IF(Patient_Data[[#This Row],[Age]]<=64,"Adult","Geriatric")) -> Adult
A117: NHM-2024-101222 | B117: =TEXT(Patient_Data!$E117,"mmmm") -> January | C117: =LEFT(B117,3) -> Jan | D117: =MONTH(Patient_Data!$E117) -> 1 | E117: 45321 | F117: =TEXT(Patient_Data[[#This Row],[Admission_Date]],"YYYY") -> 2024 | G117: Noah Murray | H117: NovaHealth Greenfield Clinic | I117: Male | J117: 69 | K117: Readmitted | L117: 4 | M117: Orthopedics | N117: =IF(M117="Cardiology","Cardio",IF(M117="Intensive Care Unit","ICU",IF(M117="Neurology","Neuro",IF(M117="Emergency Room","ER",IF(M117="Pediatrics","PD",IF(M117="Surgery","Surgery",IF(M117="General Medicine","GM",IF(M117="Orthopedics","Ortho","")))))))) -> Ortho | O117: 13290.19 | P117: 9775.44 | Q117: 9.2 | R117: =IF(Patient_Data!$L117<2,"Low Risk",IF(Patient_Data!$L117<4,"Moderate Risk","High Risk")) -> High Risk | S117: =IF(Patient_Data[[#This Row],[Age]]<=18,"Pediatric",IF(Patient_Data[[#This Row],[Age]]<=64,"Adult","Geriatric")) -> Geriatric
A118: NHM-2024-100850 | B118: =TEXT(Patient_Data!$E118,"mmmm") -> March | C118: =LEFT(B118,3) -> Mar | D118: =MONTH(Patient_Data!$E118) -> 3 | E118: 45367 | F118: =TEXT(Patient_Data[[#This Row],[Admission_Date]],"YYYY") -> 2024 | G118: Justin Morris | H118: NovaHealth Greenfield Clinic | I118: Female | J118: 70 | K118: Discharged | L118: 3 | M118: General Medicine | N118: =IF(M118="Cardiology","Cardio",IF(M118="Intensive Care Unit","ICU",IF(M118="Neurology","Neuro",IF(M118="Emergency Room","ER",IF(M118="Pediatrics","PD",IF(M118="Surgery","Surgery",IF(M118="General Medicine","GM",IF(M118="Orthopedics","Ortho","")))))))) -> GM | O118: 4408.36 | P118: 3423.15 | Q118: 9.1 | R118: =IF(Patient_Data!$L118<2,"Low Risk",IF(Patient_Data!$L118<4,"Moderate Risk","High Risk")) -> Moderate Risk | S118: =IF(Patient_Data[[#This Row],[Age]]<=18,"Pediatric",IF(Patient_Data[[#This Row],[Age]]<=64,"Adult","Geriatric")) -> Geriatric
A119: NHM-2023-101928 | B119: =TEXT(Patient_Data!$E119,"mmmm") -> September | C119: =LEFT(B119,3) -> Sep | D119: =MONTH(Patient_Data!$E119) -> 9 | E119: 45197 | F119: =TEXT(Patient_Data[[#This Row],[Admission_Date]],"YYYY") -> 2023 | G119: Sandra Ortiz | H119: NovaHealth River Valley Hospital | I119: Female | J119: 52 | K119: Discharged | L119: 3 | M119: Cardiology | N119: =IF(M119="Cardiology","Cardio",IF(M119="Intensive Care Unit","ICU",IF(M119="Neurology","Neuro",IF(M119="Emergency Room","ER",IF(M119="Pediatrics","PD",IF(M119="Surgery","Surgery",IF(M119="General Medicine","GM",IF(M119="Orthopedics","Ortho","")))))))) -> Cardio | O119: 14505.45 | P119: 8445.96 | Q119: 4.1 | R119: =IF(Patient_Data!$L119<2,"Low Risk",IF(Patient_Data!$L119<4,"Moderate Risk","High Risk")) -> Moderate Risk | S119: =IF(Patient_Data[[#This Row],[Age]]<=18,"Pediatric",IF(Patient_Data[[#This Row],[Age]]<=64,"Adult","Geriatric")) -> Adult
A120: NHM-2023-101259 | B120: =TEXT(Patient_Data!$E120,"mmmm") -> March | C120: =LEFT(B120,3) -> Mar | D120: =MONTH(Patient_Data!$E120) -> 3 | E120: 45358 | F120: =TEXT(Patient_Data[[#This Row],[Admission_Date]],"YYYY") -> 2024 | G120: Juan Lewis | H120: NovaHealth Chicago Medical Center | I120: Female | J120: 58 | K120: Discharged | L120: 1 | M120: Orthopedics | N120: =IF(M120="Cardiology","Cardio",IF(M120="Intensive Care Unit","ICU",IF(M120="Neurology","Neuro",IF(M120="Emergency Room","ER",IF(M120="Pediatrics","PD",IF(M120="Surgery","Surgery",IF(M120="General Medicine","GM",IF(M120="Orthopedics","Ortho","")))))))) -> Ortho | O120: 4112.98 | P120: 2565.72 | Q120: 7.1 | R120: =IF(Patient_Data!$L120<2,"Low Risk",IF(Patient_Data!$L120<4,"Moderate Risk","High Risk")) -> Low Risk | S120: =IF(Patient_Data[[#This Row],[Age]]<=18,"Pediatric",IF(Patient_Data[[#This Row],[Age]]<=64,"Adult","Geriatric")) -> Adult
... A173: NHM-2024-101413 | B173: =TEXT(Patient_Data!$E173,"mmmm") -> November | C173: =LEFT(B173,3) -> Nov | D173: =MONTH(Patient_Data!$E173) -> 11 | E173: 45257 | F173: =TEXT(Patient_Data[[#This Row],[Admission_Date]],"YYYY") -> 2023 | G173: Sean Robinson | H173: NovaHealth Metro General Hospital | I173: Female | J173: 80 | K173: In-Patient Care | L173: 4 | M173: Neurology | N173: =IF(M173="Cardiology","Cardio",IF(M173="Intensive Care Unit","ICU",IF(M173="Neurology","Neuro",IF(M173="Emergency Room","ER",IF(M173="Pediatrics","PD",IF(M173="Surgery","Surgery",IF(M173="General Medicine","GM",IF(M173="Orthopedics","Ortho","")))))))) -> Neuro | O173: 13840.27 | P173: 10169 | Q173: 8.2 | R173: =IF(Patient_Data!$L173<2,"Low Risk",IF(Patient_Data!$L173<4,"Moderate Risk","High Risk")) -> High Risk | S173: =IF(Patient_Data[[#This Row],[Age]]<=18,"Pediatric",IF(Patient_Data[[#This Row],[Age]]<=64,"Adult","Geriatric")) -> Geriatric
...

Sheet Dashboard

Sheet Tools
B3: Logo
G5: `
B11: Colors
B13: Background Color | C13: #66FFCC
B14: Overlay Color | C14: #000000
B15: Cards and Charts Background | C15: #111111
